<?xml version="1.0" encoding="UTF-8"?>
<testng-results ignored="0" total="1" passed="0" failed="1" skipped="0">
  <reporter-output>
  </reporter-output>
  <suite started-at="2024-11-18T14:19:59 IST" name="Default suite" finished-at="2024-11-18T14:20:04 IST" duration-ms="5036">
    <groups>
    </groups>
    <test started-at="2024-11-18T14:19:59 IST" name="Default test" finished-at="2024-11-18T14:20:04 IST" duration-ms="5036">
      <class name="testcase.NegativeTestCases">
        <test-method is-config="true" signature="loadTestData()[pri:0, instance:testcase.NegativeTestCases@48aca48b]" started-at="2024-11-18T14:19:59 IST" name="loadTestData" finished-at="2024-11-18T14:19:59 IST" duration-ms="18" status="PASS">
          <reporter-output>
          </reporter-output>
        </test-method> <!-- loadTestData -->
        <test-method is-config="true" signature="Setup()[pri:0, instance:testcase.NegativeTestCases@48aca48b]" started-at="2024-11-18T14:20:00 IST" name="Setup" finished-at="2024-11-18T14:20:03 IST" duration-ms="3756" status="PASS">
          <reporter-output>
          </reporter-output>
        </test-method> <!-- Setup -->
        <test-method signature="testDynamicTableWithNegativeData()[pri:0, instance:testcase.NegativeTestCases@48aca48b]" started-at="2024-11-18T14:20:03 IST" name="testDynamicTableWithNegativeData" finished-at="2024-11-18T14:20:04 IST" duration-ms="824" status="FAIL">
          <exception class="java.lang.AssertionError">
            <message>
              <![CDATA[Test failed due to unexpected exception.]]>
            </message>
            <full-stacktrace>
              <![CDATA[java.lang.AssertionError: Test failed due to unexpected exception.
at org.testng.Assert.fail(Assert.java:99)
at testcase.NegativeTestCases.testDynamicTableWithNegativeData(NegativeTestCases.java:91)
at java.base/jdk.internal.reflect.NativeMethodAccessorImpl.invoke0(Native Method)
at java.base/jdk.internal.reflect.NativeMethodAccessorImpl.invoke(NativeMethodAccessorImpl.java:77)
at java.base/jdk.internal.reflect.DelegatingMethodAccessorImpl.invoke(DelegatingMethodAccessorImpl.java:43)
at java.base/java.lang.reflect.Method.invoke(Method.java:568)
at org.testng.internal.MethodInvocationHelper.invokeMethod(MethodInvocationHelper.java:133)
at org.testng.internal.TestInvoker.invokeMethod(TestInvoker.java:598)
at org.testng.internal.TestInvoker.invokeTestMethod(TestInvoker.java:173)
at org.testng.internal.MethodRunner.runInSequence(MethodRunner.java:46)
at org.testng.internal.TestInvoker$MethodInvocationAgent.invoke(TestInvoker.java:824)
at org.testng.internal.TestInvoker.invokeTestMethods(TestInvoker.java:146)
at org.testng.internal.TestMethodWorker.invokeTestMethods(TestMethodWorker.java:146)
at org.testng.internal.TestMethodWorker.run(TestMethodWorker.java:128)
at java.base/java.util.ArrayList.forEach(ArrayList.java:1511)
at org.testng.TestRunner.privateRun(TestRunner.java:794)
at org.testng.TestRunner.run(TestRunner.java:596)
at org.testng.SuiteRunner.runTest(SuiteRunner.java:377)
at org.testng.SuiteRunner.runSequentially(SuiteRunner.java:371)
at org.testng.SuiteRunner.privateRun(SuiteRunner.java:332)
at org.testng.SuiteRunner.run(SuiteRunner.java:276)
at org.testng.SuiteRunnerWorker.runSuite(SuiteRunnerWorker.java:53)
at org.testng.SuiteRunnerWorker.run(SuiteRunnerWorker.java:96)
at org.testng.TestNG.runSuitesSequentially(TestNG.java:1212)
at org.testng.TestNG.runSuitesLocally(TestNG.java:1134)
at org.testng.TestNG.runSuites(TestNG.java:1063)
at org.testng.TestNG.run(TestNG.java:1031)
at org.testng.remote.AbstractRemoteTestNG.run(AbstractRemoteTestNG.java:115)
at org.testng.remote.RemoteTestNG.initAndRun(RemoteTestNG.java:251)
at org.testng.remote.RemoteTestNG.main(RemoteTestNG.java:77)
]]>
            </full-stacktrace>
          </exception> <!-- java.lang.AssertionError -->
          <reporter-output>
          </reporter-output>
        </test-method> <!-- testDynamicTableWithNegativeData -->
        <test-method is-config="true" signature="captureScreenshotOnFailure(org.testng.ITestResult)[pri:0, instance:testcase.NegativeTestCases@48aca48b]" started-at="2024-11-18T14:20:04 IST" name="captureScreenshotOnFailure" finished-at="2024-11-18T14:20:04 IST" duration-ms="391" status="PASS">
          <params>
            <param index="0">
              <value>
                <![CDATA[[TestResult name=testDynamicTableWithNegativeData status=FAILURE method=NegativeTestCases.testDynamicTableWithNegativeData()[pri:0, instance:testcase.NegativeTestCases@48aca48b] output={null}]]]>
              </value>
            </param>
          </params>
          <reporter-output>
          </reporter-output>
        </test-method> <!-- captureScreenshotOnFailure -->
      </class> <!-- testcase.NegativeTestCases -->
    </test> <!-- Default test -->
  </suite> <!-- Default suite -->
</testng-results>
